<?xml version='1.0'?>
<sdf version="1.9">
  <model name="aruco_marker_line">
    <link name="chassis">
      <inertial>
        <mass>0.2</mass>
        <inertia>
          <ixx>0.001</ixx>
          <iyy>0.001</iyy>
          <izz>0.001</izz>
          <ixy>0</ixy>
          <ixz>0</ixz>
          <iyz>0</iyz>
        </inertia>
      </inertial>
      
      <visual name="visual">
        <geometry>
          <box>
            <size>0.15 0.15 0.001</size>
          </box>
        </geometry>
        <material>
          <diffuse>1.0 1.0 1.0 1</diffuse>
          <specular>0.5 0.5 0.5 1</specular>
          <pbr>
            <metal>
              <albedo_map>materials/textures/aruco_marker.png</albedo_map>
            </metal>
          </pbr>
        </material>
      </visual>
      
      <collision name="collision">
        <geometry>
          <box>
            <size>0.15 0.15 0.001</size>
          </box>
        </geometry>
      </collision>
    </link>
    
    <!-- Simple Virtual Wheels (invisible) -->
    <link name="left_wheel">
      <pose>0 0.1 0 0 1.5707 0</pose>
      <inertial>
        <mass>0.1</mass>
        <inertia>
          <ixx>0.0001</ixx>
          <iyy>0.0001</iyy>
          <izz>0.0001</izz>
          <ixy>0</ixy>
          <ixz>0</ixz>
          <iyz>0</iyz>
        </inertia>
      </inertial>
    </link>
    
    <link name="right_wheel">
      <pose>0 -0.1 0 0 1.5707 0</pose>
      <inertial>
        <mass>0.1</mass>
        <inertia>
          <ixx>0.0001</ixx>
          <iyy>0.0001</iyy>
          <izz>0.0001</izz>
          <ixy>0</ixy>
          <ixz>0</ixz>
          <iyz>0</iyz>
        </inertia>
      </inertial>
    </link>
    
    <!-- Joints -->
    <joint name="left_wheel_joint" type="revolute">
      <parent>chassis</parent>
      <child>left_wheel</child>
      <axis>
        <xyz>0 0 1</xyz>
        <limit>
          <lower>-1e+16</lower>
          <upper>1e+16</upper>
        </limit>
      </axis>
    </joint>
    
    <joint name="right_wheel_joint" type="revolute">
      <parent>chassis</parent>
      <child>right_wheel</child>
      <axis>
        <xyz>0 0 1</xyz>
        <limit>
          <lower>-1e+16</lower>
          <upper>1e+16</upper>
        </limit>
      </axis>
    </joint>
    
    <!-- DiffDrive Plugin -->
    <plugin
      filename="gz-sim-diff-drive-system"
      name="gz::sim::systems::DiffDrive">
      <left_joint>left_wheel_joint</left_joint>
      <right_joint>right_wheel_joint</right_joint>
      <wheel_separation>0.2</wheel_separation>
      <wheel_radius>0.05</wheel_radius>
      <odom_publish_frequency>10</odom_publish_frequency>
      <topic>cmd_vel</topic>
    </plugin>
    
    <!-- Linear movement publisher -->
    <plugin filename="gz-sim-triggered-publisher-system"
            name="gz::sim::systems::TriggeredPublisher">
      <input type="gz.msgs.Clock" topic="/clock">
      </input>
      <output type="gz.msgs.Twist" topic="cmd_vel">
        linear: {x: 0.7}
      </output>
    </plugin>
  </model>
</sdf>